Workbook

Sheet 任务清单
A1: 模块 | B1: 子模块 | C1: 任务名称 | D1: 优先级 | E1: 负责人 | F1: 计划完成时间 | G1: 状态 | H1: 实际完成时间 | I1: 备注
A2: ESP32设备端 | B2: 音频模块 | C2: 自定义唤醒词 | D2: 高 | E2: 张明旭 | F2: 2026/4/7 | G2: 已完成 | H2: 2026/3/31 | I2: 原表已有
C3: 音频驱动 | D3: 高 | E3: 张明旭 | F3: 2026/4/7 | G3: 已完成 | H3: 2026/4/3 | I3: 原表已有
C4: 咪头AEC、VAD功能 | D4: 高 | E4: 张明旭 | F4: 2026/4/13 | G4: 已完成 | H4: 2026/4/13 | I4: 原表已有
C5: mqtt消费及推送 | D5: 中 | E5: 张明旭 | F5: 2026/4/13 | G5: 已完成 | H5: 2026/4/13 | I5: 原表已有
C6: 调用云端语音对话WebSocket | D6: 高 | E6: 张明旭 | F6: 2026/4/13 | G6: 已完成 | H6: 2026/4/13 | I6: 原表已有
C7: 环形缓冲区播放opus音频流 | D7: 高 | E7: 张明旭 | F7: 2026/4/13 | G7: 已完成 | H7: 2026/4/13 | I7: 原表已有
C8: 防止网络波动断音破片增加一个暂存缓冲 | D8: 高 | E8: 张明旭 | F8: 2026/4/13 | G8: 已完成 | H8: 2026/4/13 | I8: 原表已有
C9: OPUS编码参数定型（24kbps CBR、禁用VBR） | D9: 高 | E9: 张明旭 | G9: 已完成 | H9: 2026/5/20 | I9: 补录·DEC-001
C10: 音频处理器静音接口（防TTS打断重播） | D10: 中 | E10: 张明旭 | G10: 已完成 | H10: 2026/5/25 | I10: 补录
C11: 扬声器音量接口+NVS持久化+MQTT远程调音量 | D11: 中 | E11: 张明旭 | G11: 已完成 | H11: 2026/6/1 | I11: 补录
C12: 长句TTS丢帧/溢出优化（解码输入缓冲扩到32KB+限频告警） | D12: 高 | E12: 张明旭 | G12: 已完成 | H12: 2026/7/2 | I12: 补录
C13: TTS期唤醒打断阈值调优（0.18→0.3 降AEC残留误触） | D13: 中 | E13: 张明旭 | G13: 已完成 | H13: 2026/7/2 | I13: 补录
C14: ES8311上电爆音—软件软启动方案 | D14: 中 | E14: 张明旭 | G14: 已完成 | H14: 2026/6/15 | I14: 补录·实测无效（VMID模拟瞬态）
C15: ES8311上电爆音—NMOS延时开关硬件方案 | D15: 中 | E15: 张明旭 | G15: 未开始 | I15: 需改板：2N7002压CTRL，C_g 10uF+R_g 470k≈3.4s
C16: 离线音频播放（MP3 + P3/OPUS 双格式） | D16: 高 | E16: 张明旭 | G16: 进行中 | I16: 代码已合入2026/7/16，出声/泄漏/仲裁待烧录验证
C17: 多轮对话尾音误触EOS / 超时截断修复 | D17: 高 | E17: 张明旭 | G17: 已完成 | H17: 2026/7/3 | I17: 补录·BUG-007/013/014/021
B18: 初始化 | C18: 蓝牙连接 | D18: 高 | E18: 张明旭 | F18: 2026/3/16 | G18: 已完成 | H18: 2026/3/16 | I18: 原表已有
C19: 接收wifi凭证 | D19: 高 | E19: 张明旭 | F19: 2026/3/17 | G19: 已完成 | H19: 2026/3/17 | I19: 原表已有
C20: 设备联网 | D20: 高 | E20: 张明旭 | F20: 2026/3/17 | G20: 已完成 | H20: 2026/3/17 | I20: 原表已有
C21: 获取token | D21: 高 | E21: 张明旭 | F21: 2026/4/10 | G21: 已完成 | H21: 2026/4/10 | I21: 原表已有
C22: Token双重刷新机制（2h过期，主动+被动） | D22: 高 | E22: 张明旭 | G22: 已完成 | H22: 2026/4/10 | I22: 补录·DEC-003
C23: 配网协议迁移 Unified Provisioning → BluFi（NimBLE） | D23: 高 | E23: 张明旭 | G23: 已完成 | H23: 2026/6/22 | I23: 补录
C24: 动态蓝牙设备名（MAC派生 EchoPals-XXXXXX） | D24: 中 | E24: 张明旭 | G24: 已完成 | H24: 2026/6/23 | I24: 补录
C25: 裸板模式编译裁剪（CONFIG_BSP_HAS_DISPLAY） | D25: 低 | E25: 张明旭 | G25: 已完成 | H25: 2026/6/23 | I25: 补录
C26: BluFi CustomData下发token | D26: 高 | E26: 张明旭 | G26: 进行中 | I26: 配网联网+下发已通，卡在deviceToken缺失待后端
C27: 配网二维码显示 | D27: 中 | E27: 张明旭 | G27: 进行中 | I27: BUG-029双根因已修，待烧录验证
C28: 按键长按重置WiFi | D28: 高 | E28: 张明旭 | G28: 进行中 | I28: BUG-030 LVGL未init断言崩，已定位待改
C29: BluFi分支BLE初始化崩溃排查 | D29: 高 | E29: 张明旭 | G29: 进行中 | I29: BUG-026 已加esp_intr_dump诊断待烧录
C30: 前端配网对接说明文档 | D30: 低 | E30: 张明旭 | G30: 已完成 | H30: 2026/7/2 | I30: 补录
B31: 备份升级 | C31: OTA | D31: 高 | E31: 张明旭 | F31: 2026/6/ | G31: 已完成 | I31: 原表已有
C32: OTA进度回调+SHA256校验+重启后补发 | D32: 高 | E32: 张明旭 | G32: 已完成 | H32: 2026/6/17 | I32: 补录
C33: OTA推送+云端连通性探测工具 | D33: 中 | E33: 张明旭 | G33: 已完成 | H33: 2026/7/7 | I33: 补录
C34: OTA前停唤醒词/触摸扫描（防并发崩） | D34: 高 | E34: 张明旭 | G34: 已完成 | H34: 2026/7/20 | I34: 补录
C35: app分区容量告急（仅剩2%） | D35: 高 | E35: 张明旭 | G35: 未开始 | I35: 需重划分区表或裁剪固件
B36: 屏幕模块 | C36: 屏幕驱动 | D36: 高 | E36: 张明旭 | F36: 2026/4/12 | G36: 已完成 | H36: 2026/4/12 | I36: 原表已有
C37: 显示天气 | D37: 中 | E37: 张明旭 | F37: 2026/5/8 | G37: 已完成 | H37: 2026/5/6 | I37: 原表已有
C38: 显示日历 | D38: 中 | E38: 张明旭 | F38: 2026/5/8 | G38: 已完成 | H38: 2026/5/7 | I38: 原表已有
C39: 显示时间 | D39: 中 | E39: 张明旭 | F39: 2026/4/30 | G39: 已完成 | H39: 2026/5/2 | I39: 原表已有
C40: 闹钟提醒 | D40: 中 | E40: 张明旭 | F40: 2026/4/30 | G40: 已完成 | H40: 2026/5/2 | I40: 原表已有
...

Sheet 总览
A1: Echo2 项目任务总览
A2: 生成日期 2026-07-23 数据来源：git 提交记录 + memory 日志 + 现有代码
A4: 状态 | B4: 条数 | C4: 占比
A5: 已完成 | B5: =COUNTIF(任务清单!$G$2:$G$95,A5) | C5: =IF($B$8=0,0,B5/$B$8)
A6: 进行中 | B6: =COUNTIF(任务清单!$G$2:$G$95,A6) | C6: =IF($B$8=0,0,B6/$B$8)
A7: 未开始 | B7: =COUNTIF(任务清单!$G$2:$G$95,A7) | C7: =IF($B$8=0,0,B7/$B$8)
A8: 合计 | B8: =COUNTA(任务清单!$G$2:$G$95) | C8: 1
A10: 子模块 | B10: 已完成 | C10: 进行中 | D10: 未开始 | E10: 小计
A11: 音频模块 | B11: =COUNTIFS(任务清单!$B$2:$B$95,$A11,任务清单!$G$2:$G$95,"已完成") | C11: =COUNTIFS(任务清单!$B$2:$B$95,$A11,任务清单!$G$2:$G$95,"进行中") | D11: =COUNTIFS(任务清单!$B$2:$B$95,$A11,任务清单!$G$2:$G$95,"未开始") | E11: =COUNTIF(任务清单!$B$2:$B$95,$A11)
A12: 初始化 | B12: =COUNTIFS(任务清单!$B$2:$B$95,$A12,任务清单!$G$2:$G$95,"已完成") | C12: =COUNTIFS(任务清单!$B$2:$B$95,$A12,任务清单!$G$2:$G$95,"进行中") | D12: =COUNTIFS(任务清单!$B$2:$B$95,$A12,任务清单!$G$2:$G$95,"未开始") | E12: =COUNTIF(任务清单!$B$2:$B$95,$A12)
A13: 备份升级 | B13: =COUNTIFS(任务清单!$B$2:$B$95,$A13,任务清单!$G$2:$G$95,"已完成") | C13: =COUNTIFS(任务清单!$B$2:$B$95,$A13,任务清单!$G$2:$G$95,"进行中") | D13: =COUNTIFS(任务清单!$B$2:$B$95,$A13,任务清单!$G$2:$G$95,"未开始") | E13: =COUNTIF(任务清单!$B$2:$B$95,$A13)
A14: 屏幕模块 | B14: =COUNTIFS(任务清单!$B$2:$B$95,$A14,任务清单!$G$2:$G$95,"已完成") | C14: =COUNTIFS(任务清单!$B$2:$B$95,$A14,任务清单!$G$2:$G$95,"进行中") | D14: =COUNTIFS(任务清单!$B$2:$B$95,$A14,任务清单!$G$2:$G$95,"未开始") | E14: =COUNTIF(任务清单!$B$2:$B$95,$A14)
A15: 游戏模块 | B15: =COUNTIFS(任务清单!$B$2:$B$95,$A15,任务清单!$G$2:$G$95,"已完成") | C15: =COUNTIFS(任务清单!$B$2:$B$95,$A15,任务清单!$G$2:$G$95,"进行中") | D15: =COUNTIFS(任务清单!$B$2:$B$95,$A15,任务清单!$G$2:$G$95,"未开始") | E15: =COUNTIF(任务清单!$B$2:$B$95,$A15)
A16: 交互模块 | B16: =COUNTIFS(任务清单!$B$2:$B$95,$A16,任务清单!$G$2:$G$95,"已完成") | C16: =COUNTIFS(任务清单!$B$2:$B$95,$A16,任务清单!$G$2:$G$95,"进行中") | D16: =COUNTIFS(任务清单!$B$2:$B$95,$A16,任务清单!$G$2:$G$95,"未开始") | E16: =COUNTIF(任务清单!$B$2:$B$95,$A16)
A17: 电源与低功耗 | B17: =COUNTIFS(任务清单!$B$2:$B$95,$A17,任务清单!$G$2:$G$95,"已完成") | C17: =COUNTIFS(任务清单!$B$2:$B$95,$A17,任务清单!$G$2:$G$95,"进行中") | D17: =COUNTIFS(任务清单!$B$2:$B$95,$A17,任务清单!$G$2:$G$95,"未开始") | E17: =COUNTIF(任务清单!$B$2:$B$95,$A17)
A18: 存储与资源 | B18: =COUNTIFS(任务清单!$B$2:$B$95,$A18,任务清单!$G$2:$G$95,"已完成") | C18: =COUNTIFS(任务清单!$B$2:$B$95,$A18,任务清单!$G$2:$G$95,"进行中") | D18: =COUNTIFS(任务清单!$B$2:$B$95,$A18,任务清单!$G$2:$G$95,"未开始") | E18: =COUNTIF(任务清单!$B$2:$B$95,$A18)
A19: 稳定性与内存 | B19: =COUNTIFS(任务清单!$B$2:$B$95,$A19,任务清单!$G$2:$G$95,"已完成") | C19: =COUNTIFS(任务清单!$B$2:$B$95,$A19,任务清单!$G$2:$G$95,"进行中") | D19: =COUNTIFS(任务清单!$B$2:$B$95,$A19,任务清单!$G$2:$G$95,"未开始") | E19: =COUNTIF(任务清单!$B$2:$B$95,$A19)
A20: 离线能力 | B20: =COUNTIFS(任务清单!$B$2:$B$95,$A20,任务清单!$G$2:$G$95,"已完成") | C20: =COUNTIFS(任务清单!$B$2:$B$95,$A20,任务清单!$G$2:$G$95,"进行中") | D20: =COUNTIFS(任务清单!$B$2:$B$95,$A20,任务清单!$G$2:$G$95,"未开始") | E20: =COUNTIF(任务清单!$B$2:$B$95,$A20)
A21: 协议 | B21: =COUNTIFS(任务清单!$B$2:$B$95,$A21,任务清单!$G$2:$G$95,"已完成") | C21: =COUNTIFS(任务清单!$B$2:$B$95,$A21,任务清单!$G$2:$G$95,"进行中") | D21: =COUNTIFS(任务清单!$B$2:$B$95,$A21,任务清单!$G$2:$G$95,"未开始") | E21: =COUNTIF(任务清单!$B$2:$B$95,$A21)
